package io.smallrye.reactive.unimulti.operators;

import static io.smallrye.reactive.unimulti.helpers.ParameterValidation.SUPPLIER_PRODUCED_NULL;
import static io.smallrye.reactive.unimulti.helpers.ParameterValidation.nonNull;

import java.util.function.Function;
import java.util.function.Predicate;

import io.smallrye.reactive.unimulti.CompositeException;
import io.smallrye.reactive.unimulti.Uni;

public class UniMapOnFailure<I, O> extends UniOperator<I, O> {

    private final Function<? super Throwable, ? extends Throwable> mapper;
    private final Predicate<? super Throwable> predicate;

    public UniMapOnFailure(Uni<I> upstream,
            Predicate<? super Throwable> predicate,
            Function<? super Throwable, ? extends Throwable> mapper) {
        super(nonNull(upstream, "upstream"));
        this.mapper = nonNull(mapper, "mapper");
        this.predicate = nonNull(predicate, "predicate");
    }

    @Override
    protected void subscribing(UniSerializedSubscriber<? super O> subscriber) {
        upstream().subscribe().withSubscriber(new UniDelegatingSubscriber<I, O>(subscriber) {

            @Override
            public void onFailure(Throwable failure) {
                if (subscriber.isCancelledOrDone()) {
                    // Avoid calling the mapper if we are done to save some cycles.
                    // If the cancellation happen during the call, the events won't be dispatched.
                    return;
                }
                boolean test;
                try {
                    test = predicate.test(failure);
                } catch (RuntimeException e) {
                    subscriber.onFailure(new CompositeException(failure, e));
                    return;
                }

                if (test) {
                    Throwable outcome;
                    try {
                        outcome = mapper.apply(failure);
                        // We cannot call onFailure here, as if onFailure would throw an exception
                        // it would be caught and onFailure would be called. This would be illegal.
                    } catch (Exception e) {
                        subscriber.onFailure(e);
                        return;
                    }
                    if (outcome == null) {
                        subscriber.onFailure(new NullPointerException(SUPPLIER_PRODUCED_NULL));
                    } else {
                        subscriber.onFailure(outcome);
                    }
                } else {
                    subscriber.onFailure(failure);
                }
            }

        });
    }
}
